Workbook

Sheet START HERE
B2: Order Fulfilment & Installation Performance Analysis Dashboard
B3: Business Operations Analytics Case Study for Neo Heat Pump - Sai Heating and Cooling Solutions
B5: IMPORTANT - SIMULATED DATA: all 160 orders are synthetic records generated for a portfolio case study. They do not describe real orders, customers, prices or performance of the company. Findings illustrate an analysis method; recommendations are proposals only.
B7: What this is | C7: An operations-analysis workbook that turns raw order records into KPIs, a management dashboard, findings and recommendations for order fulfilment, delivery and installation.
B8: Why it was built | C8: Management needs one reliable view of: how many orders are done, pending or cancelled; whether deliveries and installations keep their promised dates; which open orders are overdue; and where the process gets stuck.
B9: Data period | C9: Orders booked 1-Jan-2026 to 30-Jun-2026. Report as-of date: 30-Jun-2026 (editable on KPI ANALYSIS, cell C4).
B10: Prepared by | C10: [Your Name] - portfolio project (not an employee report).
B12: HOW TO NAVIGATE (click a sheet name)
B13: OPERATIONS DASHBOARD | C13: Start here if you have 2 minutes: KPI cards, 6 charts, overdue-order list. Yellow boxes filter everything.
B14: KPI ANALYSIS | C14: Every KPI with formula, numerator, denominator, exclusions and interpretation.
B15: PIVOT ANALYSIS | C15: Summary tables by product, month, customer type, region, stage and delay reason.
B16: BUSINESS RECOMMENDATIONS | C16: Findings (with live supporting numbers) and 9 prioritised recommendations.
B17: CLEANED DATA | C17: The validated dataset. Dark headers = inputs, teal headers = formula columns.
B18: RAW DATA | C18: The original export, untouched, including its errors.
B19: DATA QUALITY LOG | C19: Live quality checks, the cleaning rules and every cell that was changed or flagged.
B20: DATA DICTIONARY | C20: Meaning of every column in RAW and CLEANED data.
B22: HOW TO READ THE DASHBOARD
B23: Order completion | C23: Completed (installed) orders ÷ non-cancelled orders. Recent orders that are not due yet still count as open, so June looks lower.
B24: On-time delivery | C24: Deliveries on or before the promised date ÷ deliveries with valid dates. Undelivered and cancelled orders are not in this rate.
B25: Installation completion | C25: Installations that were due by the as-of date and are done ÷ installations due.
B26: Overdue | C26: An open order past the promise for the stage it is in. A promise after the as-of date is 'not yet due', never overdue.
B27: Colours | C27: Teal = performance, red = late/overdue, amber = in progress, grey = cancelled/neutral.
B29: TOOLS
C30: Excel formulas (COUNTIFS, SUMIFS, AVERAGEIFS, INDEX/MATCH, LARGE, SUMPRODUCT), named cells, data validation dropdowns, conditional formatting, charts. The file was generated with Python (pandas, openpyxl) and recalculated in LibreOffice; open it in Excel and press Ctrl+Alt+F9 once to force a full recalculation. PivotTables/slicers are not included because the generator cannot create them - PIVOT ANALYSIS gives formula equivalents and 5 steps to add one.

Sheet RAW DATA
A1: RAW DATA - original export exactly as received (do not edit)
A2: SIMULATED DATA - synthetic records created for a portfolio case study. Not real company performance.
A3: 163 rows including 3 duplicate rows and deliberate data-entry problems. Values are stored as text, as an export would deliver them. The cleaned version is on CLEANED DATA.
A5: Order ID | B5: Order Date | C5: Customer Ref | D5: Customer Type | E5: Region | F5: Product Category | G5: Units | H5: Order Value (INR) | I5: Expected Delivery | J5: Dispatch Date | K5: Delivery Date | L5: Expected Installation | M5: Installation Date | N5: Status | O5: Delivery Delay Reason | P5: Installation Delay Reason | Q5: Cancellation Reason | R5: Notes
A6: NHP-0001 | B6: 03-01-2026 | C6: CUST-7126 | D6: Institutional | E6: Other States | F6: Commercial Heat Pump | G6: 2 | H6: 794000 | I6: 25-01-2026 | J6: 09-01-2026 | K6: 15-01-2026 | L6: 30-01-2026 | M6: 20-01-2026 | N6: Completed
A7: NHP-0002 | B7: 08-01-2026 | C7: CUST-6574 | D7: Institutional | E7: Other States | F7: Commercial Heat Pump | G7: 2 | H7: 1090000 | I7: 30-01-2026 | J7: 03-02-2026 | K7: 18-02-2026 | L7: 04-02-2026 | M7: 23-02-2026 | N7: Completed | O7: Component shortage | P7: Knock-on from late delivery | R7: Customer requested weekend install
A8: NHP-0003 | B8: 10-01-2026 | C8: CUST-4483 | D8: Commercial | E8: Bengaluru | F8: Commercial Heat Pump | G8: 4 | H8: 2232000 | I8: 28-01-2026 | J8: 31-01-2026 | K8: 02-02-2026 | L8: 02-02-2026 | M8: 06-02-2026 | N8: Completed | O8: Component shortage | R8: Site survey done
A9: NHP-0004 | B9: 12-01-2026 | C9: CUST-6930 | D9: Commercial | E9: Rest of Karnataka | F9: Heat Pump Dryer | G9: 1 | H9: 783000 | I9: 04-02-2026 | J9: 01-02-2026 | K9: 05-02-2026 | L9: 09-02-2026 | M9: 13-02-2026 | N9: Completed | O9: Production backlog | P9: Technician availability | R9: Site survey done
A10: NHP-0005 | B10: 15-01-2026 | C10: CUST-7543 | D10: Institutional | E10: Other States | F10: Commercial Heat Pump | G10: 3 | H10: 1998000 | I10: 06-02-2026 | J10: 02-02-2026 | K10: 11-02-2026 | L10: 11-02-2026 | M10: 28-02-2026 | N10: Completed | O10: Production backlog | R10: Site survey done
A11: NHP-0006 | B11: 21-01-2026 | C11: CUST-5374 | D11: Institutional | E11: Bengaluru | F11: Custom Requirement | G11: 2 | H11: 2244000 | I11: 20-02-2026 | J11: 18-02-2026 | K11: 20-02-2026 | L11: 25-02-2026 | M11: 17-02-2026 | N11: Completed | R11: Site survey done
A12: NHP-0007 | B12: 22-01-2026 | C12: CUST-6573 | D12: Commercial | E12: Bengaluru | F12: Custom Requirement | G12: 1 | H12: 783000 | I12: 21-02-2026 | J12: 19-02-2026 | K12: 31-02-2026 | L12: 26-02-2026 | M12: 25-02-2026 | N12: COMPLETED | R12: Electrical load checked
A13: NHP-0008 | B13: 2026/01/23 | C13: CUST-5339 | D13: Institutional | E13: Bengaluru | F13: Commercial Heat Pump | G13: 2 | H13: 1038000 | I13: 10-02-2026 | J13: 31-01-2026 | K13: 02-02-2026 | L13: 15-02-2026 | M13: 16-02-2026 | N13: Completed | R13: Customer requested weekend install
A14: NHP-0009 | B14: 24-01-2026 | C14: CUST-1520 | D14: Institutional | E14: Bengaluru | F14: Commercial Heat Pump | G14: 2 | H14: 1594000 | I14: 11-02-2026 | J14: 15-02-2026 | K14: 16-02-2026 | L14: 16-02-2026 | M14: 19-02-2026 | N14: Completed | O14: Component shortage | P14: Knock-on from late delivery
A15: NHP-0010 | B15: 26-01-2026 | C15: CUST-2679 | D15: Residential | E15: Bengaluru | F15: Swimming Pool Heat Pump | G15: 1 | H15: 249000 | I15: 09-02-2026 | J15: 04-02-2026 | K15: 05-02-2026 | L15: 12-02-2026 | M15: 06-02-2026 | N15: Completed | R15: Customer requested weekend install
A16: NHP-0011 | B16: 29-01-2026 | C16: CUST-6881 | D16: Commercial | E16: Rest of Karnataka | F16: Heat Pump Dryer | G16: 2 | H16: 846000 | I16: 21-02-2026 | J16: 22-02-2026 | K16: 26-02-2026 | L16: 26-02-2026 | M16: 01-03-2026 | N16: Completed | O16: Production backlog | P16: Knock-on from late delivery
A17: NHP-0012 | B17: 29-01-2026 | C17: CUST-5374 | D17: Residential | E17: Other States | F17: Heat Pump Water Heater | G17: 1 | H17: 174000 | I17: 12-02-2026 | J17: 01-02-2026 | K17: 08-02-2026 | L17: 15-02-2026 | M17: 09-02-2026 | N17: Completed
A18: NHP-0013 | B18: 30-01-2026 | C18: CUST-9669 | D18: Residential | E18: Rest of Karnataka | F18: Heat Pump Water Heater | G18: 1 | H18: 131000 | I18: 11-02-2026 | J18: 07-02-2026 | K18: 11-02-2026 | L18: 14-02-2026 | M18: 12-02-2026 | N18: Completed | R18: Replacement of old geyser
A19: NHP-0014 | B19: 01-02-2026 | C19: CUST-2519 | D19: Institutional | E19: Bengaluru | F19: Commercial Heat Pump | G19: 1 | H19: 448000 | I19: 19-02-2026 | J19: 13-02-2026 | K19: 15-02-2026 | L19: 24-02-2026 | M19: 18-02-2026 | N19: Completed | R19: Customer requested weekend install
A20: NHP-0015 | B20: 02-02-2026 | C20: CUST-5315 | D20: Commercial | E20: Rest of Karnataka | F20: Commercial Heat Pump | G20: 1 | H20: 798000 | I20: 22-02-2026 | J20: 24-02-2026 | K20: 26-02-2026 | L20: 27-02-2026 | M20: 03-03-2026 | N20: Completed | O20: Production backlog | P20: Knock-on from late delivery | R20: Electrical load checked
A21: NHP-0016 | B21: 03-02-2026 | C21: CUST-6573 | D21: Commercial | E21: Other States | F21: Heat Pump Dryer | G21: 1 | H21: 574000 | I21: 28-02-2026 | J21: 26-02-2026 | K21: 08-03-2026 | L21: 05-03-2026 | M21: 19-03-2026 | N21: Completed | O21: Component shortage | P21: Customer site not ready
A22: NHP-0017 | B22: 03-02-2026 | C22: CUST-1488 | D22: Commercial | E22: Bengaluru | F22: Custom Requirement | G22: 2 | H22: 2040000 | I22: 05-03-2026 | J22: 11-02-2026 | K22: 13-02-2026 | L22: 10-03-2026 | N22: Cancelled | Q22: Customer postponed project | R22: Unit returned to factory after delivery
A23: NHP-0018 | B23: 03-02-2026 | C23: CUST-3621 | D23: Commercial | E23: Rest of Karnataka | F23: Custom Requirement | G23: 1 | H23: 1311000 | I23: 07-03-2026 | J23: 04-03-2026 | K23: 08-03-2026 | L23: 12-03-2026 | M23: 13-03-2026 | N23: Completed | O23: Production backlog | P23: Knock-on from late delivery
A24: NHP-0019 | B24: 07-02-2026 | C24: CUST-7065 | D24: Commercial | E24: Bengaluru | F24: Heat Pump Dryer | G24: 2 | H24: 1122000 | I24: 28-02-2026 | J24: 25-02-2026 | K24: 26-02-2026 | L24: 05-03-2026 | M24: 12-03-2026 | N24: Completed
A25: NHP-0020 | B25: 07-02-2026 | C25: CUST-3340 | D25: Residential | E25: Other States | F25: HP Water Heater | G25: 1 | H25: 160000 | I25: 21-02-2026 | J25: 12-02-2026 | K25: 21-02-2026 | L25: 24-02-2026 | M25: 26-02-2026 | N25: Completed | P25: Technician availability | R25: Electrical load checked
A26: NHP-0021 | B26: 08-02-2026 | C26: CUST-4657 | D26: residential | E26: Bengaluru | F26: Heat Pump Water Heater | G26: 1 | H26: 153000 | I26: 18-02-2026 | J26: 12-02-2026 | L26: 21-02-2026 | N26: Canceled | Q26: Long lead time
A27: NHP-0022 | B27: 09-02-2026 | C27: CUST-4811 | D27: Commercial | E27: Bengaluru | F27: Pool Heat Pump | G27: 2 | H27: 870000 | I27: 23-02-2026 | J27: 17-02-2026 | K27: 18-02-2026 | L27: 26-02-2026 | M27: 20-02-2026 | N27: completed | R27: Site survey done
A28: NHP-0023 | B28: 10-02-2026 | C28: CUST-1916 | D28: Institutional | E28: Bengaluru | F28: Custom Requirement | G28: 2 | H28: 1898000 | I28: 12-03-2026 | L28: 17-03-2026 | N28: Canceled | Q28: Price / budget | R28: Electrical load checked
A29: NHP-0024 | B29: 11-02-2026 | C29: CUST-2824 | D29: Commercial | E29: Bengaluru | F29: Custom Requirement | G29: 2 | H29: 1434000 | I29: 13-03-2026 | J29: 05-03-2026 | K29: 06-03-2026 | L29: 18-03-2026 | M29: 19-03-2026 | N29: Completed | P29: Customer site not ready | R29: Pipe routing confirmed
A30: NHP-0025 | B30: 14-02-2026 | C30: CUST-4657 | D30: Residential | E30: Rest of Karnataka | F30: Heat Pump Water Heater | G30: 1 | H30: 157000 | I30: 26-02-2026 | J30: 19-02-2026 | K30: 22-02-2026 | L30: 01-03-2026 | M30: 23-02-2026 | N30: Completed | R30: Pipe routing confirmed
A31: NHP-0026 | B31: 14-02-2026 | C31: CUST-7126 | D31: Comm. | E31: Bengaluru | F31: Swimming Pool Heat Pump | G31: 2 | H31: 632000 | I31: 28-02-2026 | J31: 25-02-2026 | K31: 27-02-2026 | L31: 03-03-2026 | M31: 28-02-2026 | N31: Completed | R31: Pipe routing confirmed
A32: NHP-0027 | B32: 17-02-2026 | C32: CUST-3664 | D32: Residential | E32: Rest of Karnataka | F32: HP Water Heater | G32: 1 | H32: 185000 | I32: 01-03-2026 | J32: 21-02-2026 | K32: 25-02-2026 | L32: 04-03-2026 | M32: 27-02-2026 | N32: Completed | R32: Customer requested weekend install
A33: NHP-0028 | B33: 17-02-2026 | C33: CUST-6574 | D33: Commercial | E33: Bengaluru | F33: Custom Requirement | G33: 2 | H33: 1670000 | I33: 19-03-2026 | J33: 27-03-2026 | K33: 28-03-2026 | L33: 24-03-2026 | M33: 01-04-2026 | N33: Completed | O33: Production backlog
A34: NHP-0029 | B34: 18-02-2026 | C34: CUST-4432 | D34: Commercial | E34: Bengaluru | F34: Swimming Pool Heat Pump | G34: 2 | H34: 900000 | I34: 04-03-2026 | J34: 27-02-2026 | K34: 01-03-2026 | L34: 07-03-2026 | M34: 03-03-2026 | N34: Completed
A35: NHP-0030 | B35: 20-02-2026 | C35: CUST-9669 | D35: Institutional | E35: Bengaluru | F35: Commercial Heat Pump | G35: 3 | H35: 3144000 | I35: 10-03-2026 | J35: 15-03-2026 | K35: 17-03-2026 | L35: 15-03-2026 | M35: 22-03-2026 | N35: Completed | O35: Production backlog | P35: Knock-on from late delivery | R35: Replacement of old geyser
A36: NHP-0031 | B36: 20-02-2026 | C36: CUST-5808 | D36: Commercial | E36: Bengaluru | F36: Heat Pump Dryer | G36: 1 | H36: 619000 | I36: 13-03-2026 | J36: 24-02-2026 | K36: 26-02-2026 | L36: 18-03-2026 | M36: 03-03-2026 | N36: Completed | R36: Replacement of old geyser
A37: NHP-0031 | B37: 20-02-2026 | C37: CUST-5808 | D37: Commercial | E37: Bengaluru | F37: Heat Pump Dryer | G37: 1 | H37: 619000 | I37: 13-03-2026 | J37: 24-02-2026 | K37: 26-02-2026 | L37: 18-03-2026 | M37: 03-03-2026 | N37: Completed | R37: Replacement of old geyser
A38: NHP-0032 | B38: 2026/02/24 | C38: CUST-5119 | D38: Residential | E38: Rest of Karnataka | F38: Heat Pump Water Heater | G38: 1 | H38: 183000 | I38: 08-03-2026 | J38: 04-03-2026 | K38: 08-03-2026 | L38: 11-03-2026 | M38: 16-03-2026 | N38: Completed
A39: NHP-0033 | B39: 24-02-2026 | C39: CUST-4150 | D39: Commercial | E39: Bengaluru | F39: Commercial Heat Pump | G39: 4 | H39: 2952000 | I39: 14-03-2026 | J39: 17-03-2026 | K39: 18-03-2026 | L39: 19-03-2026 | M39: 15-03-2026 | N39: Completed | P39: Knock-on from late delivery
A40: NHP-0034 | B40: 25-02-2026 | C40: CUST-3547 | D40: Commercial | E40: Bengaluru | F40: Swimming Pool Heat Pump | G40: 2 | H40: 488000 | I40: 11-03-2026 | J40: 02-03-2026 | K40: 04-03-2026 | L40: 14-03-2026 | M40: 16-03-2026 | N40: Completed | P40: Customer site not ready
A41: NHP-0035 | B41: 25-02-2026 | C41: CUST-8428 | D41: Residential | E41: Bengaluru | F41: Swimming Pool Heat Pump | G41: 1 | I41: 11-03-2026 | J41: 12-03-2026 | K41: 14-03-2026 | L41: 14-03-2026 | M41: 17-03-2026 | N41: Completed | O41: Production backlog | P41: Knock-on from late delivery
...

Sheet CLEANED DATA
A1: Order_ID | B1: Order_Date | C1: Customer_Ref | D1: Customer_Type | E1: Region | F1: Product_Category | G1: Units | H1: Order_Value_INR | I1: Expected_Delivery_Date | J1: Dispatch_Date | K1: Actual_Delivery_Date | L1: Expected_Installation_Date | M1: Actual_Installation_Date | N1: Order_Status | O1: Delivery_Delay_Reason | P1: Installation_Delay_Reason | Q1: Cancellation_Reason | R1: Operational_Notes | S1: DQ_Flag | T1: Valid_Dispatch_Timing | U1: Valid_Delivery_Timing | V1: Valid_Install_Timing | W1: Order_Month | X1: Delivery_Due | Y1: Delivered | Z1: Delivery_Delay_Days | AA1: Delivery_Timeliness | AB1: Install_Due | AC1: Installed | AD1: Install_Delay_Days | AE1: Install_Timeliness | AF1: Production_Days | AG1: Transit_Days | AH1: Install_Lead_Days | AI1: Order_To_Delivery_Days | AJ1: Order_Cycle_Days | AK1: Current_Stage | AL1: Overdue | AM1: Days_Overdue | AN1: Overdue_Stage | AO1: In_Dashboard_Filter | AP1: Overdue_Rank_Key | AR1: Dark headers = validated input values. Teal headers = formulas (do not type over).
A2: NHP-0001 | B2: 46025 | C2: CUST-7126 | D2: Institutional | E2: Other States | F2: Commercial Heat Pump | G2: 2 | H2: 794000 | I2: 46047 | J2: 46031 | K2: 46037 | L2: 46052 | M2: 46042 | N2: Completed | S2: OK | T2: 1 | U2: 1 | V2: 1 | W2: =DATE(YEAR(B2),MONTH(B2),1) -> 46023 | X2: =IF(AND(N2<>"Cancelled",I2<=AsOf),1,0) -> 1 | Y2: =IF(AND(N2<>"Cancelled",OR(ISNUMBER(K2),N2="Completed")),1,0) -> 1 | Z2: =IF(AND(Y2=1,U2=1,ISNUMBER(K2)),K2-I2,"") -> -10 | AA2: =IF(Z2="","",IF(Z2<0,"Early",IF(Z2=0,"On Time","Late"))) -> Early | AB2: =IF(AND(N2<>"Cancelled",L2<=AsOf),1,0) -> 1 | AC2: =IF(AND(N2<>"Cancelled",OR(ISNUMBER(M2),N2="Completed")),1,0) -> 1 | AD2: =IF(AND(AC2=1,V2=1,ISNUMBER(M2)),M2-L2,"") -> -10 | AE2: =IF(AD2="","",IF(AD2<0,"Early",IF(AD2=0,"On Time","Late"))) -> Early | AF2: =IF(AND(T2=1,ISNUMBER(J2),N2<>"Cancelled"),J2-B2,"") -> 6 | AG2: =IF(AND(AF2<>"",Z2<>""),K2-J2,"") -> 6 | AH2: =IF(AND(Z2<>"",AD2<>""),M2-K2,"") -> 5 | AI2: =IF(Z2<>"",K2-B2,"") -> 12 | AJ2: =IF(AND(N2="Completed",AD2<>""),M2-B2,"") -> 17 | AK2: =IF(N2="Cancelled","Cancelled",IF(N2="Completed","Completed",IF(Y2=1,"Awaiting Installation",IF(ISNUMBER(J2),"In Transit","In Production")))) -> Completed | AL2: =IF(AND(N2="Pending",OR(AND(Y2=0,I2<AsOf),AND(Y2=1,L2<AsOf))),1,0) -> 0 | AM2: =IF(AL2=1,IF(Y2=0,AsOf-I2,AsOf-L2),"") | AN2: =IF(AL2=1,IF(Y2=0,"Delivery","Installation"),"") | AO2: =IF(AND(OR(fCat="All",F2=fCat),OR(fCust="All",D2=fCust),OR(fReg="All",E2=fReg)),1,0) -> 1 | AP2: =IF(AND(AL2=1,AO2=1),AM2+ROW()/100000,0) -> 0
A3: NHP-0002 | B3: 46030 | C3: CUST-6574 | D3: Institutional | E3: Other States | F3: Commercial Heat Pump | G3: 2 | H3: 1090000 | I3: 46052 | J3: 46056 | K3: 46071 | L3: 46057 | M3: 46076 | N3: Completed | O3: Component shortage | P3: Knock-on from late delivery | R3: Customer requested weekend install | S3: OK | T3: 1 | U3: 1 | V3: 1 | W3: =DATE(YEAR(B3),MONTH(B3),1) -> 46023 | X3: =IF(AND(N3<>"Cancelled",I3<=AsOf),1,0) -> 1 | Y3: =IF(AND(N3<>"Cancelled",OR(ISNUMBER(K3),N3="Completed")),1,0) -> 1 | Z3: =IF(AND(Y3=1,U3=1,ISNUMBER(K3)),K3-I3,"") -> 19 | AA3: =IF(Z3="","",IF(Z3<0,"Early",IF(Z3=0,"On Time","Late"))) -> Late | AB3: =IF(AND(N3<>"Cancelled",L3<=AsOf),1,0) -> 1 | AC3: =IF(AND(N3<>"Cancelled",OR(ISNUMBER(M3),N3="Completed")),1,0) -> 1 | AD3: =IF(AND(AC3=1,V3=1,ISNUMBER(M3)),M3-L3,"") -> 19 | AE3: =IF(AD3="","",IF(AD3<0,"Early",IF(AD3=0,"On Time","Late"))) -> Late | AF3: =IF(AND(T3=1,ISNUMBER(J3),N3<>"Cancelled"),J3-B3,"") -> 26 | AG3: =IF(AND(AF3<>"",Z3<>""),K3-J3,"") -> 15 | AH3: =IF(AND(Z3<>"",AD3<>""),M3-K3,"") -> 5 | AI3: =IF(Z3<>"",K3-B3,"") -> 41 | AJ3: =IF(AND(N3="Completed",AD3<>""),M3-B3,"") -> 46 | AK3: =IF(N3="Cancelled","Cancelled",IF(N3="Completed","Completed",IF(Y3=1,"Awaiting Installation",IF(ISNUMBER(J3),"In Transit","In Production")))) -> Completed | AL3: =IF(AND(N3="Pending",OR(AND(Y3=0,I3<AsOf),AND(Y3=1,L3<AsOf))),1,0) -> 0 | AM3: =IF(AL3=1,IF(Y3=0,AsOf-I3,AsOf-L3),"") | AN3: =IF(AL3=1,IF(Y3=0,"Delivery","Installation"),"") | AO3: =IF(AND(OR(fCat="All",F3=fCat),OR(fCust="All",D3=fCust),OR(fReg="All",E3=fReg)),1,0) -> 1 | AP3: =IF(AND(AL3=1,AO3=1),AM3+ROW()/100000,0) -> 0
A4: NHP-0003 | B4: 46032 | C4: CUST-4483 | D4: Commercial | E4: Bengaluru | F4: Commercial Heat Pump | G4: 4 | H4: 2232000 | I4: 46050 | J4: 46053 | K4: 46055 | L4: 46055 | M4: 46059 | N4: Completed | O4: Component shortage | R4: Site survey done | S4: OK | T4: 1 | U4: 1 | V4: 1 | W4: =DATE(YEAR(B4),MONTH(B4),1) -> 46023 | X4: =IF(AND(N4<>"Cancelled",I4<=AsOf),1,0) -> 1 | Y4: =IF(AND(N4<>"Cancelled",OR(ISNUMBER(K4),N4="Completed")),1,0) -> 1 | Z4: =IF(AND(Y4=1,U4=1,ISNUMBER(K4)),K4-I4,"") -> 5 | AA4: =IF(Z4="","",IF(Z4<0,"Early",IF(Z4=0,"On Time","Late"))) -> Late | AB4: =IF(AND(N4<>"Cancelled",L4<=AsOf),1,0) -> 1 | AC4: =IF(AND(N4<>"Cancelled",OR(ISNUMBER(M4),N4="Completed")),1,0) -> 1 | AD4: =IF(AND(AC4=1,V4=1,ISNUMBER(M4)),M4-L4,"") -> 4 | AE4: =IF(AD4="","",IF(AD4<0,"Early",IF(AD4=0,"On Time","Late"))) -> Late | AF4: =IF(AND(T4=1,ISNUMBER(J4),N4<>"Cancelled"),J4-B4,"") -> 21 | AG4: =IF(AND(AF4<>"",Z4<>""),K4-J4,"") -> 2 | AH4: =IF(AND(Z4<>"",AD4<>""),M4-K4,"") -> 4 | AI4: =IF(Z4<>"",K4-B4,"") -> 23 | AJ4: =IF(AND(N4="Completed",AD4<>""),M4-B4,"") -> 27 | AK4: =IF(N4="Cancelled","Cancelled",IF(N4="Completed","Completed",IF(Y4=1,"Awaiting Installation",IF(ISNUMBER(J4),"In Transit","In Production")))) -> Completed | AL4: =IF(AND(N4="Pending",OR(AND(Y4=0,I4<AsOf),AND(Y4=1,L4<AsOf))),1,0) -> 0 | AM4: =IF(AL4=1,IF(Y4=0,AsOf-I4,AsOf-L4),"") | AN4: =IF(AL4=1,IF(Y4=0,"Delivery","Installation"),"") | AO4: =IF(AND(OR(fCat="All",F4=fCat),OR(fCust="All",D4=fCust),OR(fReg="All",E4=fReg)),1,0) -> 1 | AP4: =IF(AND(AL4=1,AO4=1),AM4+ROW()/100000,0) -> 0
A5: NHP-0004 | B5: 46034 | C5: CUST-6930 | D5: Commercial | E5: Rest of Karnataka | F5: Heat Pump Dryer | G5: 1 | H5: 783000 | I5: 46057 | J5: 46054 | K5: 46058 | L5: 46062 | M5: 46066 | N5: Completed | O5: Production backlog | P5: Technician availability | R5: Site survey done | S5: OK | T5: 1 | U5: 1 | V5: 1 | W5: =DATE(YEAR(B5),MONTH(B5),1) -> 46023 | X5: =IF(AND(N5<>"Cancelled",I5<=AsOf),1,0) -> 1 | Y5: =IF(AND(N5<>"Cancelled",OR(ISNUMBER(K5),N5="Completed")),1,0) -> 1 | Z5: =IF(AND(Y5=1,U5=1,ISNUMBER(K5)),K5-I5,"") -> 1 | AA5: =IF(Z5="","",IF(Z5<0,"Early",IF(Z5=0,"On Time","Late"))) -> Late | AB5: =IF(AND(N5<>"Cancelled",L5<=AsOf),1,0) -> 1 | AC5: =IF(AND(N5<>"Cancelled",OR(ISNUMBER(M5),N5="Completed")),1,0) -> 1 | AD5: =IF(AND(AC5=1,V5=1,ISNUMBER(M5)),M5-L5,"") -> 4 | AE5: =IF(AD5="","",IF(AD5<0,"Early",IF(AD5=0,"On Time","Late"))) -> Late | AF5: =IF(AND(T5=1,ISNUMBER(J5),N5<>"Cancelled"),J5-B5,"") -> 20 | AG5: =IF(AND(AF5<>"",Z5<>""),K5-J5,"") -> 4 | AH5: =IF(AND(Z5<>"",AD5<>""),M5-K5,"") -> 8 | AI5: =IF(Z5<>"",K5-B5,"") -> 24 | AJ5: =IF(AND(N5="Completed",AD5<>""),M5-B5,"") -> 32 | AK5: =IF(N5="Cancelled","Cancelled",IF(N5="Completed","Completed",IF(Y5=1,"Awaiting Installation",IF(ISNUMBER(J5),"In Transit","In Production")))) -> Completed | AL5: =IF(AND(N5="Pending",OR(AND(Y5=0,I5<AsOf),AND(Y5=1,L5<AsOf))),1,0) -> 0 | AM5: =IF(AL5=1,IF(Y5=0,AsOf-I5,AsOf-L5),"") | AN5: =IF(AL5=1,IF(Y5=0,"Delivery","Installation"),"") | AO5: =IF(AND(OR(fCat="All",F5=fCat),OR(fCust="All",D5=fCust),OR(fReg="All",E5=fReg)),1,0) -> 1 | AP5: =IF(AND(AL5=1,AO5=1),AM5+ROW()/100000,0) -> 0
A6: NHP-0005 | B6: 46037 | C6: CUST-7543 | D6: Institutional | E6: Other States | F6: Commercial Heat Pump | G6: 3 | H6: 1998000 | I6: 46059 | J6: 46055 | K6: 46064 | L6: 46064 | M6: 46081 | N6: Completed | O6: Production backlog | R6: Site survey done | S6: OK | T6: 1 | U6: 1 | V6: 1 | W6: =DATE(YEAR(B6),MONTH(B6),1) -> 46023 | X6: =IF(AND(N6<>"Cancelled",I6<=AsOf),1,0) -> 1 | Y6: =IF(AND(N6<>"Cancelled",OR(ISNUMBER(K6),N6="Completed")),1,0) -> 1 | Z6: =IF(AND(Y6=1,U6=1,ISNUMBER(K6)),K6-I6,"") -> 5 | AA6: =IF(Z6="","",IF(Z6<0,"Early",IF(Z6=0,"On Time","Late"))) -> Late | AB6: =IF(AND(N6<>"Cancelled",L6<=AsOf),1,0) -> 1 | AC6: =IF(AND(N6<>"Cancelled",OR(ISNUMBER(M6),N6="Completed")),1,0) -> 1 | AD6: =IF(AND(AC6=1,V6=1,ISNUMBER(M6)),M6-L6,"") -> 17 | AE6: =IF(AD6="","",IF(AD6<0,"Early",IF(AD6=0,"On Time","Late"))) -> Late | AF6: =IF(AND(T6=1,ISNUMBER(J6),N6<>"Cancelled"),J6-B6,"") -> 18 | AG6: =IF(AND(AF6<>"",Z6<>""),K6-J6,"") -> 9 | AH6: =IF(AND(Z6<>"",AD6<>""),M6-K6,"") -> 17 | AI6: =IF(Z6<>"",K6-B6,"") -> 27 | AJ6: =IF(AND(N6="Completed",AD6<>""),M6-B6,"") -> 44 | AK6: =IF(N6="Cancelled","Cancelled",IF(N6="Completed","Completed",IF(Y6=1,"Awaiting Installation",IF(ISNUMBER(J6),"In Transit","In Production")))) -> Completed | AL6: =IF(AND(N6="Pending",OR(AND(Y6=0,I6<AsOf),AND(Y6=1,L6<AsOf))),1,0) -> 0 | AM6: =IF(AL6=1,IF(Y6=0,AsOf-I6,AsOf-L6),"") | AN6: =IF(AL6=1,IF(Y6=0,"Delivery","Installation"),"") | AO6: =IF(AND(OR(fCat="All",F6=fCat),OR(fCust="All",D6=fCust),OR(fReg="All",E6=fReg)),1,0) -> 1 | AP6: =IF(AND(AL6=1,AO6=1),AM6+ROW()/100000,0) -> 0
A7: NHP-0006 | B7: 46043 | C7: CUST-5374 | D7: Institutional | E7: Bengaluru | F7: Custom Requirement | G7: 2 | H7: 2244000 | I7: 46073 | J7: 46071 | K7: 46073 | L7: 46078 | M7: 46070 | N7: Completed | R7: Site survey done | S7: Installed before delivery | T7: 1 | U7: 1 | V7: 0 | W7: =DATE(YEAR(B7),MONTH(B7),1) -> 46023 | X7: =IF(AND(N7<>"Cancelled",I7<=AsOf),1,0) -> 1 | Y7: =IF(AND(N7<>"Cancelled",OR(ISNUMBER(K7),N7="Completed")),1,0) -> 1 | Z7: =IF(AND(Y7=1,U7=1,ISNUMBER(K7)),K7-I7,"") -> 0 | AA7: =IF(Z7="","",IF(Z7<0,"Early",IF(Z7=0,"On Time","Late"))) -> On Time | AB7: =IF(AND(N7<>"Cancelled",L7<=AsOf),1,0) -> 1 | AC7: =IF(AND(N7<>"Cancelled",OR(ISNUMBER(M7),N7="Completed")),1,0) -> 1 | AD7: =IF(AND(AC7=1,V7=1,ISNUMBER(M7)),M7-L7,"") | AE7: =IF(AD7="","",IF(AD7<0,"Early",IF(AD7=0,"On Time","Late"))) | AF7: =IF(AND(T7=1,ISNUMBER(J7),N7<>"Cancelled"),J7-B7,"") -> 28 | AG7: =IF(AND(AF7<>"",Z7<>""),K7-J7,"") -> 2 | AH7: =IF(AND(Z7<>"",AD7<>""),M7-K7,"") | AI7: =IF(Z7<>"",K7-B7,"") -> 30 | AJ7: =IF(AND(N7="Completed",AD7<>""),M7-B7,"") | AK7: =IF(N7="Cancelled","Cancelled",IF(N7="Completed","Completed",IF(Y7=1,"Awaiting Installation",IF(ISNUMBER(J7),"In Transit","In Production")))) -> Completed | AL7: =IF(AND(N7="Pending",OR(AND(Y7=0,I7<AsOf),AND(Y7=1,L7<AsOf))),1,0) -> 0 | AM7: =IF(AL7=1,IF(Y7=0,AsOf-I7,AsOf-L7),"") | AN7: =IF(AL7=1,IF(Y7=0,"Delivery","Installation"),"") | AO7: =IF(AND(OR(fCat="All",F7=fCat),OR(fCust="All",D7=fCust),OR(fReg="All",E7=fReg)),1,0) -> 1 | AP7: =IF(AND(AL7=1,AO7=1),AM7+ROW()/100000,0) -> 0
A8: NHP-0007 | B8: 46044 | C8: CUST-6573 | D8: Commercial | E8: Bengaluru | F8: Custom Requirement | G8: 1 | H8: 783000 | I8: 46074 | J8: 46072 | L8: 46079 | M8: 46078 | N8: Completed | R8: Electrical load checked | S8: Invalid Delivery Date | T8: 1 | U8: 0 | V8: 1 | W8: =DATE(YEAR(B8),MONTH(B8),1) -> 46023 | X8: =IF(AND(N8<>"Cancelled",I8<=AsOf),1,0) -> 1 | Y8: =IF(AND(N8<>"Cancelled",OR(ISNUMBER(K8),N8="Completed")),1,0) -> 1 | Z8: =IF(AND(Y8=1,U8=1,ISNUMBER(K8)),K8-I8,"") | AA8: =IF(Z8="","",IF(Z8<0,"Early",IF(Z8=0,"On Time","Late"))) | AB8: =IF(AND(N8<>"Cancelled",L8<=AsOf),1,0) -> 1 | AC8: =IF(AND(N8<>"Cancelled",OR(ISNUMBER(M8),N8="Completed")),1,0) -> 1 | AD8: =IF(AND(AC8=1,V8=1,ISNUMBER(M8)),M8-L8,"") -> -1 | AE8: =IF(AD8="","",IF(AD8<0,"Early",IF(AD8=0,"On Time","Late"))) -> Early | AF8: =IF(AND(T8=1,ISNUMBER(J8),N8<>"Cancelled"),J8-B8,"") -> 28 | AG8: =IF(AND(AF8<>"",Z8<>""),K8-J8,"") | AH8: =IF(AND(Z8<>"",AD8<>""),M8-K8,"") | AI8: =IF(Z8<>"",K8-B8,"") | AJ8: =IF(AND(N8="Completed",AD8<>""),M8-B8,"") -> 34 | AK8: =IF(N8="Cancelled","Cancelled",IF(N8="Completed","Completed",IF(Y8=1,"Awaiting Installation",IF(ISNUMBER(J8),"In Transit","In Production")))) -> Completed | AL8: =IF(AND(N8="Pending",OR(AND(Y8=0,I8<AsOf),AND(Y8=1,L8<AsOf))),1,0) -> 0 | AM8: =IF(AL8=1,IF(Y8=0,AsOf-I8,AsOf-L8),"") | AN8: =IF(AL8=1,IF(Y8=0,"Delivery","Installation"),"") | AO8: =IF(AND(OR(fCat="All",F8=fCat),OR(fCust="All",D8=fCust),OR(fReg="All",E8=fReg)),1,0) -> 1 | AP8: =IF(AND(AL8=1,AO8=1),AM8+ROW()/100000,0) -> 0
A9: NHP-0008 | B9: 46045 | C9: CUST-5339 | D9: Institutional | E9: Bengaluru | F9: Commercial Heat Pump | G9: 2 | H9: 1038000 | I9: 46063 | J9: 46053 | K9: 46055 | L9: 46068 | M9: 46069 | N9: Completed | R9: Customer requested weekend install | S9: OK | T9: 1 | U9: 1 | V9: 1 | W9: =DATE(YEAR(B9),MONTH(B9),1) -> 46023 | X9: =IF(AND(N9<>"Cancelled",I9<=AsOf),1,0) -> 1 | Y9: =IF(AND(N9<>"Cancelled",OR(ISNUMBER(K9),N9="Completed")),1,0) -> 1 | Z9: =IF(AND(Y9=1,U9=1,ISNUMBER(K9)),K9-I9,"") -> -8 | AA9: =IF(Z9="","",IF(Z9<0,"Early",IF(Z9=0,"On Time","Late"))) -> Early | AB9: =IF(AND(N9<>"Cancelled",L9<=AsOf),1,0) -> 1 | AC9: =IF(AND(N9<>"Cancelled",OR(ISNUMBER(M9),N9="Completed")),1,0) -> 1 | AD9: =IF(AND(AC9=1,V9=1,ISNUMBER(M9)),M9-L9,"") -> 1 | AE9: =IF(AD9="","",IF(AD9<0,"Early",IF(AD9=0,"On Time","Late"))) -> Late | AF9: =IF(AND(T9=1,ISNUMBER(J9),N9<>"Cancelled"),J9-B9,"") -> 8 | AG9: =IF(AND(AF9<>"",Z9<>""),K9-J9,"") -> 2 | AH9: =IF(AND(Z9<>"",AD9<>""),M9-K9,"") -> 14 | AI9: =IF(Z9<>"",K9-B9,"") -> 10 | AJ9: =IF(AND(N9="Completed",AD9<>""),M9-B9,"") -> 24 | AK9: =IF(N9="Cancelled","Cancelled",IF(N9="Completed","Completed",IF(Y9=1,"Awaiting Installation",IF(ISNUMBER(J9),"In Transit","In Production")))) -> Completed | AL9: =IF(AND(N9="Pending",OR(AND(Y9=0,I9<AsOf),AND(Y9=1,L9<AsOf))),1,0) -> 0 | AM9: =IF(AL9=1,IF(Y9=0,AsOf-I9,AsOf-L9),"") | AN9: =IF(AL9=1,IF(Y9=0,"Delivery","Installation"),"") | AO9: =IF(AND(OR(fCat="All",F9=fCat),OR(fCust="All",D9=fCust),OR(fReg="All",E9=fReg)),1,0) -> 1 | AP9: =IF(AND(AL9=1,AO9=1),AM9+ROW()/100000,0) -> 0
A10: NHP-0009 | B10: 46046 | C10: CUST-1520 | D10: Institutional | E10: Bengaluru | F10: Commercial Heat Pump | G10: 2 | H10: 1594000 | I10: 46064 | J10: 46068 | K10: 46069 | L10: 46069 | M10: 46072 | N10: Completed | O10: Component shortage | P10: Knock-on from late delivery | S10: OK | T10: 1 | U10: 1 | V10: 1 | W10: =DATE(YEAR(B10),MONTH(B10),1) -> 46023 | X10: =IF(AND(N10<>"Cancelled",I10<=AsOf),1,0) -> 1 | Y10: =IF(AND(N10<>"Cancelled",OR(ISNUMBER(K10),N10="Completed")),1,0) -> 1 | Z10: =IF(AND(Y10=1,U10=1,ISNUMBER(K10)),K10-I10,"") -> 5 | AA10: =IF(Z10="","",IF(Z10<0,"Early",IF(Z10=0,"On Time","Late"))) -> Late | AB10: =IF(AND(N10<>"Cancelled",L10<=AsOf),1,0) -> 1 | AC10: =IF(AND(N10<>"Cancelled",OR(ISNUMBER(M10),N10="Completed")),1,0) -> 1 | AD10: =IF(AND(AC10=1,V10=1,ISNUMBER(M10)),M10-L10,"") -> 3 | AE10: =IF(AD10="","",IF(AD10<0,"Early",IF(AD10=0,"On Time","Late"))) -> Late | AF10: =IF(AND(T10=1,ISNUMBER(J10),N10<>"Cancelled"),J10-B10,"") -> 22 | AG10: =IF(AND(AF10<>"",Z10<>""),K10-J10,"") -> 1 | AH10: =IF(AND(Z10<>"",AD10<>""),M10-K10,"") -> 3 | AI10: =IF(Z10<>"",K10-B10,"") -> 23 | AJ10: =IF(AND(N10="Completed",AD10<>""),M10-B10,"") -> 26 | AK10: =IF(N10="Cancelled","Cancelled",IF(N10="Completed","Completed",IF(Y10=1,"Awaiting Installation",IF(ISNUMBER(J10),"In Transit","In Production")))) -> Completed | AL10: =IF(AND(N10="Pending",OR(AND(Y10=0,I10<AsOf),AND(Y10=1,L10<AsOf))),1,0) -> 0 | AM10: =IF(AL10=1,IF(Y10=0,AsOf-I10,AsOf-L10),"") | AN10: =IF(AL10=1,IF(Y10=0,"Delivery","Installation"),"") | AO10: =IF(AND(OR(fCat="All",F10=fCat),OR(fCust="All",D10=fCust),OR(fReg="All",E10=fReg)),1,0) -> 1 | AP10: =IF(AND(AL10=1,AO10=1),AM10+ROW()/100000,0) -> 0
A11: NHP-0010 | B11: 46048 | C11: CUST-2679 | D11: Residential | E11: Bengaluru | F11: Swimming Pool Heat Pump | G11: 1 | H11: 249000 | I11: 46062 | J11: 46057 | K11: 46058 | L11: 46065 | M11: 46059 | N11: Completed | R11: Customer requested weekend install | S11: OK | T11: 1 | U11: 1 | V11: 1 | W11: =DATE(YEAR(B11),MONTH(B11),1) -> 46023 | X11: =IF(AND(N11<>"Cancelled",I11<=AsOf),1,0) -> 1 | Y11: =IF(AND(N11<>"Cancelled",OR(ISNUMBER(K11),N11="Completed")),1,0) -> 1 | Z11: =IF(AND(Y11=1,U11=1,ISNUMBER(K11)),K11-I11,"") -> -4 | AA11: =IF(Z11="","",IF(Z11<0,"Early",IF(Z11=0,"On Time","Late"))) -> Early | AB11: =IF(AND(N11<>"Cancelled",L11<=AsOf),1,0) -> 1 | AC11: =IF(AND(N11<>"Cancelled",OR(ISNUMBER(M11),N11="Completed")),1,0) -> 1 | AD11: =IF(AND(AC11=1,V11=1,ISNUMBER(M11)),M11-L11,"") -> -6 | AE11: =IF(AD11="","",IF(AD11<0,"Early",IF(AD11=0,"On Time","Late"))) -> Early | AF11: =IF(AND(T11=1,ISNUMBER(J11),N11<>"Cancelled"),J11-B11,"") -> 9 | AG11: =IF(AND(AF11<>"",Z11<>""),K11-J11,"") -> 1 | AH11: =IF(AND(Z11<>"",AD11<>""),M11-K11,"") -> 1 | AI11: =IF(Z11<>"",K11-B11,"") -> 10 | AJ11: =IF(AND(N11="Completed",AD11<>""),M11-B11,"") -> 11 | AK11: =IF(N11="Cancelled","Cancelled",IF(N11="Completed","Completed",IF(Y11=1,"Awaiting Installation",IF(ISNUMBER(J11),"In Transit","In Production")))) -> Completed | AL11: =IF(AND(N11="Pending",OR(AND(Y11=0,I11<AsOf),AND(Y11=1,L11<AsOf))),1,0) -> 0 | AM11: =IF(AL11=1,IF(Y11=0,AsOf-I11,AsOf-L11),"") | AN11: =IF(AL11=1,IF(Y11=0,"Delivery","Installation"),"") | AO11: =IF(AND(OR(fCat="All",F11=fCat),OR(fCust="All",D11=fCust),OR(fReg="All",E11=fReg)),1,0) -> 1 | AP11: =IF(AND(AL11=1,AO11=1),AM11+ROW()/100000,0) -> 0
A12: NHP-0011 | B12: 46051 | C12: CUST-6881 | D12: Commercial | E12: Rest of Karnataka | F12: Heat Pump Dryer | G12: 2 | H12: 846000 | I12: 46074 | J12: 46075 | K12: 46079 | L12: 46079 | M12: 46082 | N12: Completed | O12: Production backlog | P12: Knock-on from late delivery | S12: OK | T12: 1 | U12: 1 | V12: 1 | W12: =DATE(YEAR(B12),MONTH(B12),1) -> 46023 | X12: =IF(AND(N12<>"Cancelled",I12<=AsOf),1,0) -> 1 | Y12: =IF(AND(N12<>"Cancelled",OR(ISNUMBER(K12),N12="Completed")),1,0) -> 1 | Z12: =IF(AND(Y12=1,U12=1,ISNUMBER(K12)),K12-I12,"") -> 5 | AA12: =IF(Z12="","",IF(Z12<0,"Early",IF(Z12=0,"On Time","Late"))) -> Late | AB12: =IF(AND(N12<>"Cancelled",L12<=AsOf),1,0) -> 1 | AC12: =IF(AND(N12<>"Cancelled",OR(ISNUMBER(M12),N12="Completed")),1,0) -> 1 | AD12: =IF(AND(AC12=1,V12=1,ISNUMBER(M12)),M12-L12,"") -> 3 | AE12: =IF(AD12="","",IF(AD12<0,"Early",IF(AD12=0,"On Time","Late"))) -> Late | AF12: =IF(AND(T12=1,ISNUMBER(J12),N12<>"Cancelled"),J12-B12,"") -> 24 | AG12: =IF(AND(AF12<>"",Z12<>""),K12-J12,"") -> 4 | AH12: =IF(AND(Z12<>"",AD12<>""),M12-K12,"") -> 3 | AI12: =IF(Z12<>"",K12-B12,"") -> 28 | AJ12: =IF(AND(N12="Completed",AD12<>""),M12-B12,"") -> 31 | AK12: =IF(N12="Cancelled","Cancelled",IF(N12="Completed","Completed",IF(Y12=1,"Awaiting Installation",IF(ISNUMBER(J12),"In Transit","In Production")))) -> Completed | AL12: =IF(AND(N12="Pending",OR(AND(Y12=0,I12<AsOf),AND(Y12=1,L12<AsOf))),1,0) -> 0 | AM12: =IF(AL12=1,IF(Y12=0,AsOf-I12,AsOf-L12),"") | AN12: =IF(AL12=1,IF(Y12=0,"Delivery","Installation"),"") | AO12: =IF(AND(OR(fCat="All",F12=fCat),OR(fCust="All",D12=fCust),OR(fReg="All",E12=fReg)),1,0) -> 1 | AP12: =IF(AND(AL12=1,AO12=1),AM12+ROW()/100000,0) -> 0
A13: NHP-0012 | B13: 46051 | C13: CUST-5374 | D13: Residential | E13: Other States | F13: Heat Pump Water Heater | G13: 1 | H13: 174000 | I13: 46065 | J13: 46054 | K13: 46061 | L13: 46068 | M13: 46062 | N13: Completed | S13: OK | T13: 1 | U13: 1 | V13: 1 | W13: =DATE(YEAR(B13),MONTH(B13),1) -> 46023 | X13: =IF(AND(N13<>"Cancelled",I13<=AsOf),1,0) -> 1 | Y13: =IF(AND(N13<>"Cancelled",OR(ISNUMBER(K13),N13="Completed")),1,0) -> 1 | Z13: =IF(AND(Y13=1,U13=1,ISNUMBER(K13)),K13-I13,"") -> -4 | AA13: =IF(Z13="","",IF(Z13<0,"Early",IF(Z13=0,"On Time","Late"))) -> Early | AB13: =IF(AND(N13<>"Cancelled",L13<=AsOf),1,0) -> 1 | AC13: =IF(AND(N13<>"Cancelled",OR(ISNUMBER(M13),N13="Completed")),1,0) -> 1 | AD13: =IF(AND(AC13=1,V13=1,ISNUMBER(M13)),M13-L13,"") -> -6 | AE13: =IF(AD13="","",IF(AD13<0,"Early",IF(AD13=0,"On Time","Late"))) -> Early | AF13: =IF(AND(T13=1,ISNUMBER(J13),N13<>"Cancelled"),J13-B13,"") -> 3 | AG13: =IF(AND(AF13<>"",Z13<>""),K13-J13,"") -> 7 | AH13: =IF(AND(Z13<>"",AD13<>""),M13-K13,"") -> 1 | AI13: =IF(Z13<>"",K13-B13,"") -> 10 | AJ13: =IF(AND(N13="Completed",AD13<>""),M13-B13,"") -> 11 | AK13: =IF(N13="Cancelled","Cancelled",IF(N13="Completed","Completed",IF(Y13=1,"Awaiting Installation",IF(ISNUMBER(J13),"In Transit","In Production")))) -> Completed | AL13: =IF(AND(N13="Pending",OR(AND(Y13=0,I13<AsOf),AND(Y13=1,L13<AsOf))),1,0) -> 0 | AM13: =IF(AL13=1,IF(Y13=0,AsOf-I13,AsOf-L13),"") | AN13: =IF(AL13=1,IF(Y13=0,"Delivery","Installation"),"") | AO13: =IF(AND(OR(fCat="All",F13=fCat),OR(fCust="All",D13=fCust),OR(fReg="All",E13=fReg)),1,0) -> 1 | AP13: =IF(AND(AL13=1,AO13=1),AM13+ROW()/100000,0) -> 0
A14: NHP-0013 | B14: 46052 | C14: CUST-9669 | D14: Residential | E14: Rest of Karnataka | F14: Heat Pump Water Heater | G14: 1 | H14: 131000 | I14: 46064 | J14: 46060 | K14: 46064 | L14: 46067 | M14: 46065 | N14: Completed | R14: Replacement of old geyser | S14: OK | T14: 1 | U14: 1 | V14: 1 | W14: =DATE(YEAR(B14),MONTH(B14),1) -> 46023 | X14: =IF(AND(N14<>"Cancelled",I14<=AsOf),1,0) -> 1 | Y14: =IF(AND(N14<>"Cancelled",OR(ISNUMBER(K14),N14="Completed")),1,0) -> 1 | Z14: =IF(AND(Y14=1,U14=1,ISNUMBER(K14)),K14-I14,"") -> 0 | AA14: =IF(Z14="","",IF(Z14<0,"Early",IF(Z14=0,"On Time","Late"))) -> On Time | AB14: =IF(AND(N14<>"Cancelled",L14<=AsOf),1,0) -> 1 | AC14: =IF(AND(N14<>"Cancelled",OR(ISNUMBER(M14),N14="Completed")),1,0) -> 1 | AD14: =IF(AND(AC14=1,V14=1,ISNUMBER(M14)),M14-L14,"") -> -2 | AE14: =IF(AD14="","",IF(AD14<0,"Early",IF(AD14=0,"On Time","Late"))) -> Early | AF14: =IF(AND(T14=1,ISNUMBER(J14),N14<>"Cancelled"),J14-B14,"") -> 8 | AG14: =IF(AND(AF14<>"",Z14<>""),K14-J14,"") -> 4 | AH14: =IF(AND(Z14<>"",AD14<>""),M14-K14,"") -> 1 | AI14: =IF(Z14<>"",K14-B14,"") -> 12 | AJ14: =IF(AND(N14="Completed",AD14<>""),M14-B14,"") -> 13 | AK14: =IF(N14="Cancelled","Cancelled",IF(N14="Completed","Completed",IF(Y14=1,"Awaiting Installation",IF(ISNUMBER(J14),"In Transit","In Production")))) -> Completed | AL14: =IF(AND(N14="Pending",OR(AND(Y14=0,I14<AsOf),AND(Y14=1,L14<AsOf))),1,0) -> 0 | AM14: =IF(AL14=1,IF(Y14=0,AsOf-I14,AsOf-L14),"") | AN14: =IF(AL14=1,IF(Y14=0,"Delivery","Installation"),"") | AO14: =IF(AND(OR(fCat="All",F14=fCat),OR(fCust="All",D14=fCust),OR(fReg="All",E14=fReg)),1,0) -> 1 | AP14: =IF(AND(AL14=1,AO14=1),AM14+ROW()/100000,0) -> 0
A15: NHP-0014 | B15: 46054 | C15: CUST-2519 | D15: Institutional | E15: Bengaluru | F15: Commercial Heat Pump | G15: 1 | H15: 448000 | I15: 46072 | J15: 46066 | K15: 46068 | L15: 46077 | M15: 46071 | N15: Completed | R15: Customer requested weekend install | S15: OK | T15: 1 | U15: 1 | V15: 1 | W15: =DATE(YEAR(B15),MONTH(B15),1) -> 46054 | X15: =IF(AND(N15<>"Cancelled",I15<=AsOf),1,0) -> 1 | Y15: =IF(AND(N15<>"Cancelled",OR(ISNUMBER(K15),N15="Completed")),1,0) -> 1 | Z15: =IF(AND(Y15=1,U15=1,ISNUMBER(K15)),K15-I15,"") -> -4 | AA15: =IF(Z15="","",IF(Z15<0,"Early",IF(Z15=0,"On Time","Late"))) -> Early | AB15: =IF(AND(N15<>"Cancelled",L15<=AsOf),1,0) -> 1 | AC15: =IF(AND(N15<>"Cancelled",OR(ISNUMBER(M15),N15="Completed")),1,0) -> 1 | AD15: =IF(AND(AC15=1,V15=1,ISNUMBER(M15)),M15-L15,"") -> -6 | AE15: =IF(AD15="","",IF(AD15<0,"Early",IF(AD15=0,"On Time","Late"))) -> Early | AF15: =IF(AND(T15=1,ISNUMBER(J15),N15<>"Cancelled"),J15-B15,"") -> 12 | AG15: =IF(AND(AF15<>"",Z15<>""),K15-J15,"") -> 2 | AH15: =IF(AND(Z15<>"",AD15<>""),M15-K15,"") -> 3 | AI15: =IF(Z15<>"",K15-B15,"") -> 14 | AJ15: =IF(AND(N15="Completed",AD15<>""),M15-B15,"") -> 17 | AK15: =IF(N15="Cancelled","Cancelled",IF(N15="Completed","Completed",IF(Y15=1,"Awaiting Installation",IF(ISNUMBER(J15),"In Transit","In Production")))) -> Completed | AL15: =IF(AND(N15="Pending",OR(AND(Y15=0,I15<AsOf),AND(Y15=1,L15<AsOf))),1,0) -> 0 | AM15: =IF(AL15=1,IF(Y15=0,AsOf-I15,AsOf-L15),"") | AN15: =IF(AL15=1,IF(Y15=0,"Delivery","Installation"),"") | AO15: =IF(AND(OR(fCat="All",F15=fCat),OR(fCust="All",D15=fCust),OR(fReg="All",E15=fReg)),1,0) -> 1 | AP15: =IF(AND(AL15=1,AO15=1),AM15+ROW()/100000,0) -> 0
A16: NHP-0015 | B16: 46055 | C16: CUST-5315 | D16: Commercial | E16: Rest of Karnataka | F16: Commercial Heat Pump | G16: 1 | H16: 798000 | I16: 46075 | J16: 46077 | K16: 46079 | L16: 46080 | M16: 46084 | N16: Completed | O16: Production backlog | P16: Knock-on from late delivery | R16: Electrical load checked | S16: OK | T16: 1 | U16: 1 | V16: 1 | W16: =DATE(YEAR(B16),MONTH(B16),1) -> 46054 | X16: =IF(AND(N16<>"Cancelled",I16<=AsOf),1,0) -> 1 | Y16: =IF(AND(N16<>"Cancelled",OR(ISNUMBER(K16),N16="Completed")),1,0) -> 1 | Z16: =IF(AND(Y16=1,U16=1,ISNUMBER(K16)),K16-I16,"") -> 4 | AA16: =IF(Z16="","",IF(Z16<0,"Early",IF(Z16=0,"On Time","Late"))) -> Late | AB16: =IF(AND(N16<>"Cancelled",L16<=AsOf),1,0) -> 1 | AC16: =IF(AND(N16<>"Cancelled",OR(ISNUMBER(M16),N16="Completed")),1,0) -> 1 | AD16: =IF(AND(AC16=1,V16=1,ISNUMBER(M16)),M16-L16,"") -> 4 | AE16: =IF(AD16="","",IF(AD16<0,"Early",IF(AD16=0,"On Time","Late"))) -> Late | AF16: =IF(AND(T16=1,ISNUMBER(J16),N16<>"Cancelled"),J16-B16,"") -> 22 | AG16: =IF(AND(AF16<>"",Z16<>""),K16-J16,"") -> 2 | AH16: =IF(AND(Z16<>"",AD16<>""),M16-K16,"") -> 5 | AI16: =IF(Z16<>"",K16-B16,"") -> 24 | AJ16: =IF(AND(N16="Completed",AD16<>""),M16-B16,"") -> 29 | AK16: =IF(N16="Cancelled","Cancelled",IF(N16="Completed","Completed",IF(Y16=1,"Awaiting Installation",IF(ISNUMBER(J16),"In Transit","In Production")))) -> Completed | AL16: =IF(AND(N16="Pending",OR(AND(Y16=0,I16<AsOf),AND(Y16=1,L16<AsOf))),1,0) -> 0 | AM16: =IF(AL16=1,IF(Y16=0,AsOf-I16,AsOf-L16),"") | AN16: =IF(AL16=1,IF(Y16=0,"Delivery","Installation"),"") | AO16: =IF(AND(OR(fCat="All",F16=fCat),OR(fCust="All",D16=fCust),OR(fReg="All",E16=fReg)),1,0) -> 1 | AP16: =IF(AND(AL16=1,AO16=1),AM16+ROW()/100000,0) -> 0
A17: NHP-0016 | B17: 46056 | C17: CUST-6573 | D17: Commercial | E17: Other States | F17: Heat Pump Dryer | G17: 1 | H17: 574000 | I17: 46081 | J17: 46079 | K17: 46089 | L17: 46086 | M17: 46100 | N17: Completed | O17: Component shortage | P17: Customer site not ready | S17: OK | T17: 1 | U17: 1 | V17: 1 | W17: =DATE(YEAR(B17),MONTH(B17),1) -> 46054 | X17: =IF(AND(N17<>"Cancelled",I17<=AsOf),1,0) -> 1 | Y17: =IF(AND(N17<>"Cancelled",OR(ISNUMBER(K17),N17="Completed")),1,0) -> 1 | Z17: =IF(AND(Y17=1,U17=1,ISNUMBER(K17)),K17-I17,"") -> 8 | AA17: =IF(Z17="","",IF(Z17<0,"Early",IF(Z17=0,"On Time","Late"))) -> Late | AB17: =IF(AND(N17<>"Cancelled",L17<=AsOf),1,0) -> 1 | AC17: =IF(AND(N17<>"Cancelled",OR(ISNUMBER(M17),N17="Completed")),1,0) -> 1 | AD17: =IF(AND(AC17=1,V17=1,ISNUMBER(M17)),M17-L17,"") -> 14 | AE17: =IF(AD17="","",IF(AD17<0,"Early",IF(AD17=0,"On Time","Late"))) -> Late | AF17: =IF(AND(T17=1,ISNUMBER(J17),N17<>"Cancelled"),J17-B17,"") -> 23 | AG17: =IF(AND(AF17<>"",Z17<>""),K17-J17,"") -> 10 | AH17: =IF(AND(Z17<>"",AD17<>""),M17-K17,"") -> 11 | AI17: =IF(Z17<>"",K17-B17,"") -> 33 | AJ17: =IF(AND(N17="Completed",AD17<>""),M17-B17,"") -> 44 | AK17: =IF(N17="Cancelled","Cancelled",IF(N17="Completed","Completed",IF(Y17=1,"Awaiting Installation",IF(ISNUMBER(J17),"In Transit","In Production")))) -> Completed | AL17: =IF(AND(N17="Pending",OR(AND(Y17=0,I17<AsOf),AND(Y17=1,L17<AsOf))),1,0) -> 0 | AM17: =IF(AL17=1,IF(Y17=0,AsOf-I17,AsOf-L17),"") | AN17: =IF(AL17=1,IF(Y17=0,"Delivery","Installation"),"") | AO17: =IF(AND(OR(fCat="All",F17=fCat),OR(fCust="All",D17=fCust),OR(fReg="All",E17=fReg)),1,0) -> 1 | AP17: =IF(AND(AL17=1,AO17=1),AM17+ROW()/100000,0) -> 0
A18: NHP-0017 | B18: 46056 | C18: CUST-1488 | D18: Commercial | E18: Bengaluru | F18: Custom Requirement | G18: 2 | H18: 2040000 | I18: 46086 | J18: 46064 | K18: 46066 | L18: 46091 | N18: Cancelled | Q18: Customer postponed project | R18: Unit returned to factory after delivery | S18: Cancelled after delivery (returned) | T18: 1 | U18: 0 | V18: 1 | W18: =DATE(YEAR(B18),MONTH(B18),1) -> 46054 | X18: =IF(AND(N18<>"Cancelled",I18<=AsOf),1,0) -> 0 | Y18: =IF(AND(N18<>"Cancelled",OR(ISNUMBER(K18),N18="Completed")),1,0) -> 0 | Z18: =IF(AND(Y18=1,U18=1,ISNUMBER(K18)),K18-I18,"") | AA18: =IF(Z18="","",IF(Z18<0,"Early",IF(Z18=0,"On Time","Late"))) | AB18: =IF(AND(N18<>"Cancelled",L18<=AsOf),1,0) -> 0 | AC18: =IF(AND(N18<>"Cancelled",OR(ISNUMBER(M18),N18="Completed")),1,0) -> 0 | AD18: =IF(AND(AC18=1,V18=1,ISNUMBER(M18)),M18-L18,"") | AE18: =IF(AD18="","",IF(AD18<0,"Early",IF(AD18=0,"On Time","Late"))) | AF18: =IF(AND(T18=1,ISNUMBER(J18),N18<>"Cancelled"),J18-B18,"") | AG18: =IF(AND(AF18<>"",Z18<>""),K18-J18,"") | AH18: =IF(AND(Z18<>"",AD18<>""),M18-K18,"") | AI18: =IF(Z18<>"",K18-B18,"") | AJ18: =IF(AND(N18="Completed",AD18<>""),M18-B18,"") | AK18: =IF(N18="Cancelled","Cancelled",IF(N18="Completed","Completed",IF(Y18=1,"Awaiting Installation",IF(ISNUMBER(J18),"In Transit","In Production")))) -> Cancelled | AL18: =IF(AND(N18="Pending",OR(AND(Y18=0,I18<AsOf),AND(Y18=1,L18<AsOf))),1,0) -> 0 | AM18: =IF(AL18=1,IF(Y18=0,AsOf-I18,AsOf-L18),"") | AN18: =IF(AL18=1,IF(Y18=0,"Delivery","Installation"),"") | AO18: =IF(AND(OR(fCat="All",F18=fCat),OR(fCust="All",D18=fCust),OR(fReg="All",E18=fReg)),1,0) -> 1 | AP18: =IF(AND(AL18=1,AO18=1),AM18+ROW()/100000,0) -> 0
A19: NHP-0018 | B19: 46056 | C19: CUST-3621 | D19: Commercial | E19: Rest of Karnataka | F19: Custom Requirement | G19: 1 | H19: 1311000 | I19: 46088 | J19: 46085 | K19: 46089 | L19: 46093 | M19: 46094 | N19: Completed | O19: Production backlog | P19: Knock-on from late delivery | S19: OK | T19: 1 | U19: 1 | V19: 1 | W19: =DATE(YEAR(B19),MONTH(B19),1) -> 46054 | X19: =IF(AND(N19<>"Cancelled",I19<=AsOf),1,0) -> 1 | Y19: =IF(AND(N19<>"Cancelled",OR(ISNUMBER(K19),N19="Completed")),1,0) -> 1 | Z19: =IF(AND(Y19=1,U19=1,ISNUMBER(K19)),K19-I19,"") -> 1 | AA19: =IF(Z19="","",IF(Z19<0,"Early",IF(Z19=0,"On Time","Late"))) -> Late | AB19: =IF(AND(N19<>"Cancelled",L19<=AsOf),1,0) -> 1 | AC19: =IF(AND(N19<>"Cancelled",OR(ISNUMBER(M19),N19="Completed")),1,0) -> 1 | AD19: =IF(AND(AC19=1,V19=1,ISNUMBER(M19)),M19-L19,"") -> 1 | AE19: =IF(AD19="","",IF(AD19<0,"Early",IF(AD19=0,"On Time","Late"))) -> Late | AF19: =IF(AND(T19=1,ISNUMBER(J19),N19<>"Cancelled"),J19-B19,"") -> 29 | AG19: =IF(AND(AF19<>"",Z19<>""),K19-J19,"") -> 4 | AH19: =IF(AND(Z19<>"",AD19<>""),M19-K19,"") -> 5 | AI19: =IF(Z19<>"",K19-B19,"") -> 33 | AJ19: =IF(AND(N19="Completed",AD19<>""),M19-B19,"") -> 38 | AK19: =IF(N19="Cancelled","Cancelled",IF(N19="Completed","Completed",IF(Y19=1,"Awaiting Installation",IF(ISNUMBER(J19),"In Transit","In Production")))) -> Completed | AL19: =IF(AND(N19="Pending",OR(AND(Y19=0,I19<AsOf),AND(Y19=1,L19<AsOf))),1,0) -> 0 | AM19: =IF(AL19=1,IF(Y19=0,AsOf-I19,AsOf-L19),"") | AN19: =IF(AL19=1,IF(Y19=0,"Delivery","Installation"),"") | AO19: =IF(AND(OR(fCat="All",F19=fCat),OR(fCust="All",D19=fCust),OR(fReg="All",E19=fReg)),1,0) -> 1 | AP19: =IF(AND(AL19=1,AO19=1),AM19+ROW()/100000,0) -> 0
A20: NHP-0019 | B20: 46060 | C20: CUST-7065 | D20: Commercial | E20: Bengaluru | F20: Heat Pump Dryer | G20: 2 | H20: 1122000 | I20: 46081 | J20: 46078 | K20: 46079 | L20: 46086 | M20: 46093 | N20: Completed | S20: OK | T20: 1 | U20: 1 | V20: 1 | W20: =DATE(YEAR(B20),MONTH(B20),1) -> 46054 | X20: =IF(AND(N20<>"Cancelled",I20<=AsOf),1,0) -> 1 | Y20: =IF(AND(N20<>"Cancelled",OR(ISNUMBER(K20),N20="Completed")),1,0) -> 1 | Z20: =IF(AND(Y20=1,U20=1,ISNUMBER(K20)),K20-I20,"") -> -2 | AA20: =IF(Z20="","",IF(Z20<0,"Early",IF(Z20=0,"On Time","Late"))) -> Early | AB20: =IF(AND(N20<>"Cancelled",L20<=AsOf),1,0) -> 1 | AC20: =IF(AND(N20<>"Cancelled",OR(ISNUMBER(M20),N20="Completed")),1,0) -> 1 | AD20: =IF(AND(AC20=1,V20=1,ISNUMBER(M20)),M20-L20,"") -> 7 | AE20: =IF(AD20="","",IF(AD20<0,"Early",IF(AD20=0,"On Time","Late"))) -> Late | AF20: =IF(AND(T20=1,ISNUMBER(J20),N20<>"Cancelled"),J20-B20,"") -> 18 | AG20: =IF(AND(AF20<>"",Z20<>""),K20-J20,"") -> 1 | AH20: =IF(AND(Z20<>"",AD20<>""),M20-K20,"") -> 14 | AI20: =IF(Z20<>"",K20-B20,"") -> 19 | AJ20: =IF(AND(N20="Completed",AD20<>""),M20-B20,"") -> 33 | AK20: =IF(N20="Cancelled","Cancelled",IF(N20="Completed","Completed",IF(Y20=1,"Awaiting Installation",IF(ISNUMBER(J20),"In Transit","In Production")))) -> Completed | AL20: =IF(AND(N20="Pending",OR(AND(Y20=0,I20<AsOf),AND(Y20=1,L20<AsOf))),1,0) -> 0 | AM20: =IF(AL20=1,IF(Y20=0,AsOf-I20,AsOf-L20),"") | AN20: =IF(AL20=1,IF(Y20=0,"Delivery","Installation"),"") | AO20: =IF(AND(OR(fCat="All",F20=fCat),OR(fCust="All",D20=fCust),OR(fReg="All",E20=fReg)),1,0) -> 1 | AP20: =IF(AND(AL20=1,AO20=1),AM20+ROW()/100000,0) -> 0
A21: NHP-0020 | B21: 46060 | C21: CUST-3340 | D21: Residential | E21: Other States | F21: Heat Pump Water Heater | G21: 1 | H21: 160000 | I21: 46074 | J21: 46065 | K21: 46074 | L21: 46077 | M21: 46079 | N21: Completed | P21: Technician availability | R21: Electrical load checked | S21: OK | T21: 1 | U21: 1 | V21: 1 | W21: =DATE(YEAR(B21),MONTH(B21),1) -> 46054 | X21: =IF(AND(N21<>"Cancelled",I21<=AsOf),1,0) -> 1 | Y21: =IF(AND(N21<>"Cancelled",OR(ISNUMBER(K21),N21="Completed")),1,0) -> 1 | Z21: =IF(AND(Y21=1,U21=1,ISNUMBER(K21)),K21-I21,"") -> 0 | AA21: =IF(Z21="","",IF(Z21<0,"Early",IF(Z21=0,"On Time","Late"))) -> On Time | AB21: =IF(AND(N21<>"Cancelled",L21<=AsOf),1,0) -> 1 | AC21: =IF(AND(N21<>"Cancelled",OR(ISNUMBER(M21),N21="Completed")),1,0) -> 1 | AD21: =IF(AND(AC21=1,V21=1,ISNUMBER(M21)),M21-L21,"") -> 2 | AE21: =IF(AD21="","",IF(AD21<0,"Early",IF(AD21=0,"On Time","Late"))) -> Late | AF21: =IF(AND(T21=1,ISNUMBER(J21),N21<>"Cancelled"),J21-B21,"") -> 5 | AG21: =IF(AND(AF21<>"",Z21<>""),K21-J21,"") -> 9 | AH21: =IF(AND(Z21<>"",AD21<>""),M21-K21,"") -> 5 | AI21: =IF(Z21<>"",K21-B21,"") -> 14 | AJ21: =IF(AND(N21="Completed",AD21<>""),M21-B21,"") -> 19 | AK21: =IF(N21="Cancelled","Cancelled",IF(N21="Completed","Completed",IF(Y21=1,"Awaiting Installation",IF(ISNUMBER(J21),"In Transit","In Production")))) -> Completed | AL21: =IF(AND(N21="Pending",OR(AND(Y21=0,I21<AsOf),AND(Y21=1,L21<AsOf))),1,0) -> 0 | AM21: =IF(AL21=1,IF(Y21=0,AsOf-I21,AsOf-L21),"") | AN21: =IF(AL21=1,IF(Y21=0,"Delivery","Installation"),"") | AO21: =IF(AND(OR(fCat="All",F21=fCat),OR(fCust="All",D21=fCust),OR(fReg="All",E21=fReg)),1,0) -> 1 | AP21: =IF(AND(AL21=1,AO21=1),AM21+ROW()/100000,0) -> 0
A22: NHP-0021 | B22: 46061 | C22: CUST-4657 | D22: Residential | E22: Bengaluru | F22: Heat Pump Water Heater | G22: 1 | H22: 153000 | I22: 46071 | J22: 46065 | L22: 46074 | N22: Cancelled | Q22: Long lead time | S22: OK | T22: 1 | U22: 1 | V22: 1 | W22: =DATE(YEAR(B22),MONTH(B22),1) -> 46054 | X22: =IF(AND(N22<>"Cancelled",I22<=AsOf),1,0) -> 0 | Y22: =IF(AND(N22<>"Cancelled",OR(ISNUMBER(K22),N22="Completed")),1,0) -> 0 | Z22: =IF(AND(Y22=1,U22=1,ISNUMBER(K22)),K22-I22,"") | AA22: =IF(Z22="","",IF(Z22<0,"Early",IF(Z22=0,"On Time","Late"))) | AB22: =IF(AND(N22<>"Cancelled",L22<=AsOf),1,0) -> 0 | AC22: =IF(AND(N22<>"Cancelled",OR(ISNUMBER(M22),N22="Completed")),1,0) -> 0 | AD22: =IF(AND(AC22=1,V22=1,ISNUMBER(M22)),M22-L22,"") | AE22: =IF(AD22="","",IF(AD22<0,"Early",IF(AD22=0,"On Time","Late"))) | AF22: =IF(AND(T22=1,ISNUMBER(J22),N22<>"Cancelled"),J22-B22,"") | AG22: =IF(AND(AF22<>"",Z22<>""),K22-J22,"") | AH22: =IF(AND(Z22<>"",AD22<>""),M22-K22,"") | AI22: =IF(Z22<>"",K22-B22,"") | AJ22: =IF(AND(N22="Completed",AD22<>""),M22-B22,"") | AK22: =IF(N22="Cancelled","Cancelled",IF(N22="Completed","Completed",IF(Y22=1,"Awaiting Installation",IF(ISNUMBER(J22),"In Transit","In Production")))) -> Cancelled | AL22: =IF(AND(N22="Pending",OR(AND(Y22=0,I22<AsOf),AND(Y22=1,L22<AsOf))),1,0) -> 0 | AM22: =IF(AL22=1,IF(Y22=0,AsOf-I22,AsOf-L22),"") | AN22: =IF(AL22=1,IF(Y22=0,"Delivery","Installation"),"") | AO22: =IF(AND(OR(fCat="All",F22=fCat),OR(fCust="All",D22=fCust),OR(fReg="All",E22=fReg)),1,0) -> 1 | AP22: =IF(AND(AL22=1,AO22=1),AM22+ROW()/100000,0) -> 0
A23: NHP-0022 | B23: 46062 | C23: CUST-4811 | D23: Commercial | E23: Bengaluru | F23: Swimming Pool Heat Pump | G23: 2 | H23: 870000 | I23: 46076 | J23: 46070 | K23: 46071 | L23: 46079 | M23: 46073 | N23: Completed | R23: Site survey done | S23: OK | T23: 1 | U23: 1 | V23: 1 | W23: =DATE(YEAR(B23),MONTH(B23),1) -> 46054 | X23: =IF(AND(N23<>"Cancelled",I23<=AsOf),1,0) -> 1 | Y23: =IF(AND(N23<>"Cancelled",OR(ISNUMBER(K23),N23="Completed")),1,0) -> 1 | Z23: =IF(AND(Y23=1,U23=1,ISNUMBER(K23)),K23-I23,"") -> -5 | AA23: =IF(Z23="","",IF(Z23<0,"Early",IF(Z23=0,"On Time","Late"))) -> Early | AB23: =IF(AND(N23<>"Cancelled",L23<=AsOf),1,0) -> 1 | AC23: =IF(AND(N23<>"Cancelled",OR(ISNUMBER(M23),N23="Completed")),1,0) -> 1 | AD23: =IF(AND(AC23=1,V23=1,ISNUMBER(M23)),M23-L23,"") -> -6 | AE23: =IF(AD23="","",IF(AD23<0,"Early",IF(AD23=0,"On Time","Late"))) -> Early | AF23: =IF(AND(T23=1,ISNUMBER(J23),N23<>"Cancelled"),J23-B23,"") -> 8 | AG23: =IF(AND(AF23<>"",Z23<>""),K23-J23,"") -> 1 | AH23: =IF(AND(Z23<>"",AD23<>""),M23-K23,"") -> 2 | AI23: =IF(Z23<>"",K23-B23,"") -> 9 | AJ23: =IF(AND(N23="Completed",AD23<>""),M23-B23,"") -> 11 | AK23: =IF(N23="Cancelled","Cancelled",IF(N23="Completed","Completed",IF(Y23=1,"Awaiting Installation",IF(ISNUMBER(J23),"In Transit","In Production")))) -> Completed | AL23: =IF(AND(N23="Pending",OR(AND(Y23=0,I23<AsOf),AND(Y23=1,L23<AsOf))),1,0) -> 0 | AM23: =IF(AL23=1,IF(Y23=0,AsOf-I23,AsOf-L23),"") | AN23: =IF(AL23=1,IF(Y23=0,"Delivery","Installation"),"") | AO23: =IF(AND(OR(fCat="All",F23=fCat),OR(fCust="All",D23=fCust),OR(fReg="All",E23=fReg)),1,0) -> 1 | AP23: =IF(AND(AL23=1,AO23=1),AM23+ROW()/100000,0) -> 0
A24: NHP-0023 | B24: 46063 | C24: CUST-1916 | D24: Institutional | E24: Bengaluru | F24: Custom Requirement | G24: 2 | H24: 1898000 | I24: 46093 | L24: 46098 | N24: Cancelled | Q24: Price / budget | R24: Electrical load checked | S24: OK | T24: 1 | U24: 1 | V24: 1 | W24: =DATE(YEAR(B24),MONTH(B24),1) -> 46054 | X24: =IF(AND(N24<>"Cancelled",I24<=AsOf),1,0) -> 0 | Y24: =IF(AND(N24<>"Cancelled",OR(ISNUMBER(K24),N24="Completed")),1,0) -> 0 | Z24: =IF(AND(Y24=1,U24=1,ISNUMBER(K24)),K24-I24,"") | AA24: =IF(Z24="","",IF(Z24<0,"Early",IF(Z24=0,"On Time","Late"))) | AB24: =IF(AND(N24<>"Cancelled",L24<=AsOf),1,0) -> 0 | AC24: =IF(AND(N24<>"Cancelled",OR(ISNUMBER(M24),N24="Completed")),1,0) -> 0 | AD24: =IF(AND(AC24=1,V24=1,ISNUMBER(M24)),M24-L24,"") | AE24: =IF(AD24="","",IF(AD24<0,"Early",IF(AD24=0,"On Time","Late"))) | AF24: =IF(AND(T24=1,ISNUMBER(J24),N24<>"Cancelled"),J24-B24,"") | AG24: =IF(AND(AF24<>"",Z24<>""),K24-J24,"") | AH24: =IF(AND(Z24<>"",AD24<>""),M24-K24,"") | AI24: =IF(Z24<>"",K24-B24,"") | AJ24: =IF(AND(N24="Completed",AD24<>""),M24-B24,"") | AK24: =IF(N24="Cancelled","Cancelled",IF(N24="Completed","Completed",IF(Y24=1,"Awaiting Installation",IF(ISNUMBER(J24),"In Transit","In Production")))) -> Cancelled | AL24: =IF(AND(N24="Pending",OR(AND(Y24=0,I24<AsOf),AND(Y24=1,L24<AsOf))),1,0) -> 0 | AM24: =IF(AL24=1,IF(Y24=0,AsOf-I24,AsOf-L24),"") | AN24: =IF(AL24=1,IF(Y24=0,"Delivery","Installation"),"") | AO24: =IF(AND(OR(fCat="All",F24=fCat),OR(fCust="All",D24=fCust),OR(fReg="All",E24=fReg)),1,0) -> 1 | AP24: =IF(AND(AL24=1,AO24=1),AM24+ROW()/100000,0) -> 0
A25: NHP-0024 | B25: 46064 | C25: CUST-2824 | D25: Commercial | E25: Bengaluru | F25: Custom Requirement | G25: 2 | H25: 1434000 | I25: 46094 | J25: 46086 | K25: 46087 | L25: 46099 | M25: 46100 | N25: Completed | P25: Customer site not ready | R25: Pipe routing confirmed | S25: OK | T25: 1 | U25: 1 | V25: 1 | W25: =DATE(YEAR(B25),MONTH(B25),1) -> 46054 | X25: =IF(AND(N25<>"Cancelled",I25<=AsOf),1,0) -> 1 | Y25: =IF(AND(N25<>"Cancelled",OR(ISNUMBER(K25),N25="Completed")),1,0) -> 1 | Z25: =IF(AND(Y25=1,U25=1,ISNUMBER(K25)),K25-I25,"") -> -7 | AA25: =IF(Z25="","",IF(Z25<0,"Early",IF(Z25=0,"On Time","Late"))) -> Early | AB25: =IF(AND(N25<>"Cancelled",L25<=AsOf),1,0) -> 1 | AC25: =IF(AND(N25<>"Cancelled",OR(ISNUMBER(M25),N25="Completed")),1,0) -> 1 | AD25: =IF(AND(AC25=1,V25=1,ISNUMBER(M25)),M25-L25,"") -> 1 | AE25: =IF(AD25="","",IF(AD25<0,"Early",IF(AD25=0,"On Time","Late"))) -> Late | AF25: =IF(AND(T25=1,ISNUMBER(J25),N25<>"Cancelled"),J25-B25,"") -> 22 | AG25: =IF(AND(AF25<>"",Z25<>""),K25-J25,"") -> 1 | AH25: =IF(AND(Z25<>"",AD25<>""),M25-K25,"") -> 13 | AI25: =IF(Z25<>"",K25-B25,"") -> 23 | AJ25: =IF(AND(N25="Completed",AD25<>""),M25-B25,"") -> 36 | AK25: =IF(N25="Cancelled","Cancelled",IF(N25="Completed","Completed",IF(Y25=1,"Awaiting Installation",IF(ISNUMBER(J25),"In Transit","In Production")))) -> Completed | AL25: =IF(AND(N25="Pending",OR(AND(Y25=0,I25<AsOf),AND(Y25=1,L25<AsOf))),1,0) -> 0 | AM25: =IF(AL25=1,IF(Y25=0,AsOf-I25,AsOf-L25),"") | AN25: =IF(AL25=1,IF(Y25=0,"Delivery","Installation"),"") | AO25: =IF(AND(OR(fCat="All",F25=fCat),OR(fCust="All",D25=fCust),OR(fReg="All",E25=fReg)),1,0) -> 1 | AP25: =IF(AND(AL25=1,AO25=1),AM25+ROW()/100000,0) -> 0
A26: NHP-0025 | B26: 46067 | C26: CUST-4657 | D26: Residential | E26: Rest of Karnataka | F26: Heat Pump Water Heater | G26: 1 | H26: 157000 | I26: 46079 | J26: 46072 | K26: 46075 | L26: 46082 | M26: 46076 | N26: Completed | R26: Pipe routing confirmed | S26: OK | T26: 1 | U26: 1 | V26: 1 | W26: =DATE(YEAR(B26),MONTH(B26),1) -> 46054 | X26: =IF(AND(N26<>"Cancelled",I26<=AsOf),1,0) -> 1 | Y26: =IF(AND(N26<>"Cancelled",OR(ISNUMBER(K26),N26="Completed")),1,0) -> 1 | Z26: =IF(AND(Y26=1,U26=1,ISNUMBER(K26)),K26-I26,"") -> -4 | AA26: =IF(Z26="","",IF(Z26<0,"Early",IF(Z26=0,"On Time","Late"))) -> Early | AB26: =IF(AND(N26<>"Cancelled",L26<=AsOf),1,0) -> 1 | AC26: =IF(AND(N26<>"Cancelled",OR(ISNUMBER(M26),N26="Completed")),1,0) -> 1 | AD26: =IF(AND(AC26=1,V26=1,ISNUMBER(M26)),M26-L26,"") -> -6 | AE26: =IF(AD26="","",IF(AD26<0,"Early",IF(AD26=0,"On Time","Late"))) -> Early | AF26: =IF(AND(T26=1,ISNUMBER(J26),N26<>"Cancelled"),J26-B26,"") -> 5 | AG26: =IF(AND(AF26<>"",Z26<>""),K26-J26,"") -> 3 | AH26: =IF(AND(Z26<>"",AD26<>""),M26-K26,"") -> 1 | AI26: =IF(Z26<>"",K26-B26,"") -> 8 | AJ26: =IF(AND(N26="Completed",AD26<>""),M26-B26,"") -> 9 | AK26: =IF(N26="Cancelled","Cancelled",IF(N26="Completed","Completed",IF(Y26=1,"Awaiting Installation",IF(ISNUMBER(J26),"In Transit","In Production")))) -> Completed | AL26: =IF(AND(N26="Pending",OR(AND(Y26=0,I26<AsOf),AND(Y26=1,L26<AsOf))),1,0) -> 0 | AM26: =IF(AL26=1,IF(Y26=0,AsOf-I26,AsOf-L26),"") | AN26: =IF(AL26=1,IF(Y26=0,"Delivery","Installation"),"") | AO26: =IF(AND(OR(fCat="All",F26=fCat),OR(fCust="All",D26=fCust),OR(fReg="All",E26=fReg)),1,0) -> 1 | AP26: =IF(AND(AL26=1,AO26=1),AM26+ROW()/100000,0) -> 0
A27: NHP-0026 | B27: 46067 | C27: CUST-7126 | D27: Commercial | E27: Bengaluru | F27: Swimming Pool Heat Pump | G27: 2 | H27: 632000 | I27: 46081 | J27: 46078 | K27: 46080 | L27: 46084 | M27: 46081 | N27: Completed | R27: Pipe routing confirmed | S27: OK | T27: 1 | U27: 1 | V27: 1 | W27: =DATE(YEAR(B27),MONTH(B27),1) -> 46054 | X27: =IF(AND(N27<>"Cancelled",I27<=AsOf),1,0) -> 1 | Y27: =IF(AND(N27<>"Cancelled",OR(ISNUMBER(K27),N27="Completed")),1,0) -> 1 | Z27: =IF(AND(Y27=1,U27=1,ISNUMBER(K27)),K27-I27,"") -> -1 | AA27: =IF(Z27="","",IF(Z27<0,"Early",IF(Z27=0,"On Time","Late"))) -> Early | AB27: =IF(AND(N27<>"Cancelled",L27<=AsOf),1,0) -> 1 | AC27: =IF(AND(N27<>"Cancelled",OR(ISNUMBER(M27),N27="Completed")),1,0) -> 1 | AD27: =IF(AND(AC27=1,V27=1,ISNUMBER(M27)),M27-L27,"") -> -3 | AE27: =IF(AD27="","",IF(AD27<0,"Early",IF(AD27=0,"On Time","Late"))) -> Early | AF27: =IF(AND(T27=1,ISNUMBER(J27),N27<>"Cancelled"),J27-B27,"") -> 11 | AG27: =IF(AND(AF27<>"",Z27<>""),K27-J27,"") -> 2 | AH27: =IF(AND(Z27<>"",AD27<>""),M27-K27,"") -> 1 | AI27: =IF(Z27<>"",K27-B27,"") -> 13 | AJ27: =IF(AND(N27="Completed",AD27<>""),M27-B27,"") -> 14 | AK27: =IF(N27="Cancelled","Cancelled",IF(N27="Completed","Completed",IF(Y27=1,"Awaiting Installation",IF(ISNUMBER(J27),"In Transit","In Production")))) -> Completed | AL27: =IF(AND(N27="Pending",OR(AND(Y27=0,I27<AsOf),AND(Y27=1,L27<AsOf))),1,0) -> 0 | AM27: =IF(AL27=1,IF(Y27=0,AsOf-I27,AsOf-L27),"") | AN27: =IF(AL27=1,IF(Y27=0,"Delivery","Installation"),"") | AO27: =IF(AND(OR(fCat="All",F27=fCat),OR(fCust="All",D27=fCust),OR(fReg="All",E27=fReg)),1,0) -> 1 | AP27: =IF(AND(AL27=1,AO27=1),AM27+ROW()/100000,0) -> 0
A28: NHP-0027 | B28: 46070 | C28: CUST-3664 | D28: Residential | E28: Rest of Karnataka | F28: Heat Pump Water Heater | G28: 1 | H28: 185000 | I28: 46082 | J28: 46074 | K28: 46078 | L28: 46085 | M28: 46080 | N28: Completed | R28: Customer requested weekend install | S28: OK | T28: 1 | U28: 1 | V28: 1 | W28: =DATE(YEAR(B28),MONTH(B28),1) -> 46054 | X28: =IF(AND(N28<>"Cancelled",I28<=AsOf),1,0) -> 1 | Y28: =IF(AND(N28<>"Cancelled",OR(ISNUMBER(K28),N28="Completed")),1,0) -> 1 | Z28: =IF(AND(Y28=1,U28=1,ISNUMBER(K28)),K28-I28,"") -> -4 | AA28: =IF(Z28="","",IF(Z28<0,"Early",IF(Z28=0,"On Time","Late"))) -> Early | AB28: =IF(AND(N28<>"Cancelled",L28<=AsOf),1,0) -> 1 | AC28: =IF(AND(N28<>"Cancelled",OR(ISNUMBER(M28),N28="Completed")),1,0) -> 1 | AD28: =IF(AND(AC28=1,V28=1,ISNUMBER(M28)),M28-L28,"") -> -5 | AE28: =IF(AD28="","",IF(AD28<0,"Early",IF(AD28=0,"On Time","Late"))) -> Early | AF28: =IF(AND(T28=1,ISNUMBER(J28),N28<>"Cancelled"),J28-B28,"") -> 4 | AG28: =IF(AND(AF28<>"",Z28<>""),K28-J28,"") -> 4 | AH28: =IF(AND(Z28<>"",AD28<>""),M28-K28,"") -> 2 | AI28: =IF(Z28<>"",K28-B28,"") -> 8 | AJ28: =IF(AND(N28="Completed",AD28<>""),M28-B28,"") -> 10 | AK28: =IF(N28="Cancelled","Cancelled",IF(N28="Completed","Completed",IF(Y28=1,"Awaiting Installation",IF(ISNUMBER(J28),"In Transit","In Production")))) -> Completed | AL28: =IF(AND(N28="Pending",OR(AND(Y28=0,I28<AsOf),AND(Y28=1,L28<AsOf))),1,0) -> 0 | AM28: =IF(AL28=1,IF(Y28=0,AsOf-I28,AsOf-L28),"") | AN28: =IF(AL28=1,IF(Y28=0,"Delivery","Installation"),"") | AO28: =IF(AND(OR(fCat="All",F28=fCat),OR(fCust="All",D28=fCust),OR(fReg="All",E28=fReg)),1,0) -> 1 | AP28: =IF(AND(AL28=1,AO28=1),AM28+ROW()/100000,0) -> 0
